2023-08-22 14:24:23,121 - ERROR - Traceback (most recent call last):

2023-08-22 14:24:23,121 - ERROR -   File "C:\Users\dadmin\Desktop\ETL\ETL.py", line 185, in Create_Hash

2023-08-22 14:24:23,121 - ERROR -     valuesList = df[uniquescolumns].astype(str).apply(','.join, axis=1)

2023-08-22 14:24:23,121 - ERROR -   File "C:\Users\dadmin\Desktop\ETL\python\lib\site-packages\pandas\core\frame.py", line 3813, in __getitem__

2023-08-22 14:24:23,121 - ERROR -     indexer = self.columns._get_indexer_strict(key, "columns")[1]

2023-08-22 14:24:23,122 - ERROR -   File "C:\Users\dadmin\Desktop\ETL\python\lib\site-packages\pandas\core\indexes\base.py", line 6070, in _get_indexer_strict

2023-08-22 14:24:23,122 - ERROR -     self._raise_if_missing(keyarr, indexer, axis_name)

2023-08-22 14:24:23,122 - ERROR -   File "C:\Users\dadmin\Desktop\ETL\python\lib\site-packages\pandas\core\indexes\base.py", line 6133, in _raise_if_missing

2023-08-22 14:24:23,122 - ERROR -     raise KeyError(f"{not_found} not in index")

2023-08-22 14:24:23,122 - ERROR - KeyError: "['forestname'] not in index"

2023-08-22 14:24:23,122 - ERROR - 

2023-08-22 14:24:23,122 - ERROR - During handling of the above exception, another exception occurred:

2023-08-22 14:24:23,122 - ERROR - 

2023-08-22 14:24:23,122 - ERROR - Traceback (most recent call last):

2023-08-22 14:24:23,123 - ERROR -   File "C:\Users\dadmin\Desktop\ETL\ETL.py", line 1079, in <module>

2023-08-22 14:24:23,123 - ERROR -     main()

2023-08-22 14:24:23,123 - ERROR -   File "C:\Users\dadmin\Desktop\ETL\ETL.py", line 1043, in main

2023-08-22 14:24:23,123 - ERROR -     Part5_Comparing_Columns_In_CSV_File_And_Mysql_Match(existing_files)

2023-08-22 14:24:23,123 - ERROR -   File "C:\Users\dadmin\Desktop\ETL\ETL.py", line 843, in Part5_Comparing_Columns_In_CSV_File_And_Mysql_Match

2023-08-22 14:24:23,123 - ERROR -     insert_and_edit_mysql_tables(dfList,entity,sourcepath)

2023-08-22 14:24:23,123 - ERROR -   File "C:\Users\dadmin\Desktop\ETL\ETL.py", line 330, in insert_and_edit_mysql_tables

2023-08-22 14:24:23,123 - ERROR -     csv_df = Create_Hash(csv_df, uniqueDict[entity], pkDict[entity].lower())

2023-08-22 14:24:23,123 - ERROR -   File "C:\Users\dadmin\Desktop\ETL\ETL.py", line 193, in Create_Hash

2023-08-22 14:24:23,124 - ERROR -     PrintAndWrite("Failed in hashing:" + primarykeycolumn + '\n' + e, 1)

2023-08-22 14:24:23,124 - ERROR - TypeError: can only concatenate str (not "KeyError") to str

